2021-07-27 22:04:22,492 INFO: Microblog startup [in C:\Users\GIHYEON\anaconda3\envs\GH_project\Grand-Heart-Project\app\__init__.py:48]
2021-07-27 22:04:26,752 ERROR: Exception on /upload [GET] [in c:\users\gihyeon\appdata\local\programs\python\python39\lib\site-packages\flask\app.py:1891]
Traceback (most recent call last):
  File "c:\users\gihyeon\appdata\local\programs\python\python39\lib\site-packages\flask\app.py", line 2447, in wsgi_app
    response = self.full_dispatch_request()
  File "c:\users\gihyeon\appdata\local\programs\python\python39\lib\site-packages\flask\app.py", line 1952, in full_dispatch_request
    rv = self.handle_user_exception(e)
  File "c:\users\gihyeon\appdata\local\programs\python\python39\lib\site-packages\flask\app.py", line 1821, in handle_user_exception
    reraise(exc_type, exc_value, tb)
  File "c:\users\gihyeon\appdata\local\programs\python\python39\lib\site-packages\flask\_compat.py", line 39, in reraise
    raise value
  File "c:\users\gihyeon\appdata\local\programs\python\python39\lib\site-packages\flask\app.py", line 1950, in full_dispatch_request
    rv = self.dispatch_request()
  File "c:\users\gihyeon\appdata\local\programs\python\python39\lib\site-packages\flask\app.py", line 1936, in dispatch_request
    return self.view_functions[rule.endpoint](**req.view_args)
  File "C:\Users\GIHYEON\anaconda3\envs\GH_project\Grand-Heart-Project\app\routes.py", line 222, in add_image
    return redirect(url_for('main.image_index', msg_code=0))
  File "c:\users\gihyeon\appdata\local\programs\python\python39\lib\site-packages\flask\helpers.py", line 370, in url_for
    return appctx.app.handle_url_build_error(error, endpoint, values)
  File "c:\users\gihyeon\appdata\local\programs\python\python39\lib\site-packages\flask\app.py", line 2216, in handle_url_build_error
    reraise(exc_type, exc_value, tb)
  File "c:\users\gihyeon\appdata\local\programs\python\python39\lib\site-packages\flask\_compat.py", line 39, in reraise
    raise value
  File "c:\users\gihyeon\appdata\local\programs\python\python39\lib\site-packages\flask\helpers.py", line 357, in url_for
    rv = url_adapter.build(
  File "c:\users\gihyeon\appdata\local\programs\python\python39\lib\site-packages\werkzeug\routing.py", line 2179, in build
    raise BuildError(endpoint, values, method, self)
werkzeug.routing.BuildError: Could not build url for endpoint 'main.image_index' with values ['msg_code']. Did you mean 'image_index' instead?
2021-07-27 22:05:42,537 INFO: Microblog startup [in C:\Users\GIHYEON\anaconda3\envs\GH_project\Grand-Heart-Project\app\__init__.py:48]
2021-07-27 22:05:46,563 ERROR: Exception on /upload [GET] [in c:\users\gihyeon\appdata\local\programs\python\python39\lib\site-packages\flask\app.py:1891]
Traceback (most recent call last):
  File "c:\users\gihyeon\appdata\local\programs\python\python39\lib\site-packages\flask\app.py", line 2447, in wsgi_app
    response = self.full_dispatch_request()
  File "c:\users\gihyeon\appdata\local\programs\python\python39\lib\site-packages\flask\app.py", line 1952, in full_dispatch_request
    rv = self.handle_user_exception(e)
  File "c:\users\gihyeon\appdata\local\programs\python\python39\lib\site-packages\flask\app.py", line 1821, in handle_user_exception
    reraise(exc_type, exc_value, tb)
  File "c:\users\gihyeon\appdata\local\programs\python\python39\lib\site-packages\flask\_compat.py", line 39, in reraise
    raise value
  File "c:\users\gihyeon\appdata\local\programs\python\python39\lib\site-packages\flask\app.py", line 1950, in full_dispatch_request
    rv = self.dispatch_request()
  File "c:\users\gihyeon\appdata\local\programs\python\python39\lib\site-packages\flask\app.py", line 1936, in dispatch_request
    return self.view_functions[rule.endpoint](**req.view_args)
  File "C:\Users\GIHYEON\anaconda3\envs\GH_project\Grand-Heart-Project\app\routes.py", line 222, in add_image
    return redirect(url_for('main.image_index', msg_code=0))
  File "c:\users\gihyeon\appdata\local\programs\python\python39\lib\site-packages\flask\helpers.py", line 370, in url_for
    return appctx.app.handle_url_build_error(error, endpoint, values)
  File "c:\users\gihyeon\appdata\local\programs\python\python39\lib\site-packages\flask\app.py", line 2216, in handle_url_build_error
    reraise(exc_type, exc_value, tb)
  File "c:\users\gihyeon\appdata\local\programs\python\python39\lib\site-packages\flask\_compat.py", line 39, in reraise
    raise value
  File "c:\users\gihyeon\appdata\local\programs\python\python39\lib\site-packages\flask\helpers.py", line 357, in url_for
    rv = url_adapter.build(
  File "c:\users\gihyeon\appdata\local\programs\python\python39\lib\site-packages\werkzeug\routing.py", line 2179, in build
    raise BuildError(endpoint, values, method, self)
werkzeug.routing.BuildError: Could not build url for endpoint 'main.image_index' with values ['msg_code']. Did you mean 'image_index' instead?
2021-07-27 22:05:57,370 ERROR: Exception on /upload [GET] [in c:\users\gihyeon\appdata\local\programs\python\python39\lib\site-packages\flask\app.py:1891]
Traceback (most recent call last):
  File "c:\users\gihyeon\appdata\local\programs\python\python39\lib\site-packages\flask\app.py", line 2447, in wsgi_app
    response = self.full_dispatch_request()
  File "c:\users\gihyeon\appdata\local\programs\python\python39\lib\site-packages\flask\app.py", line 1952, in full_dispatch_request
    rv = self.handle_user_exception(e)
  File "c:\users\gihyeon\appdata\local\programs\python\python39\lib\site-packages\flask\app.py", line 1821, in handle_user_exception
    reraise(exc_type, exc_value, tb)
  File "c:\users\gihyeon\appdata\local\programs\python\python39\lib\site-packages\flask\_compat.py", line 39, in reraise
    raise value
  File "c:\users\gihyeon\appdata\local\programs\python\python39\lib\site-packages\flask\app.py", line 1950, in full_dispatch_request
    rv = self.dispatch_request()
  File "c:\users\gihyeon\appdata\local\programs\python\python39\lib\site-packages\flask\app.py", line 1936, in dispatch_request
    return self.view_functions[rule.endpoint](**req.view_args)
  File "C:\Users\GIHYEON\anaconda3\envs\GH_project\Grand-Heart-Project\app\routes.py", line 222, in add_image
    return redirect(url_for('main.image_index', msg_code=0))
  File "c:\users\gihyeon\appdata\local\programs\python\python39\lib\site-packages\flask\helpers.py", line 370, in url_for
    return appctx.app.handle_url_build_error(error, endpoint, values)
  File "c:\users\gihyeon\appdata\local\programs\python\python39\lib\site-packages\flask\app.py", line 2216, in handle_url_build_error
    reraise(exc_type, exc_value, tb)
  File "c:\users\gihyeon\appdata\local\programs\python\python39\lib\site-packages\flask\_compat.py", line 39, in reraise
    raise value
  File "c:\users\gihyeon\appdata\local\programs\python\python39\lib\site-packages\flask\helpers.py", line 357, in url_for
    rv = url_adapter.build(
  File "c:\users\gihyeon\appdata\local\programs\python\python39\lib\site-packages\werkzeug\routing.py", line 2179, in build
    raise BuildError(endpoint, values, method, self)
werkzeug.routing.BuildError: Could not build url for endpoint 'main.image_index' with values ['msg_code']. Did you mean 'image_index' instead?
2021-07-27 22:11:33,061 INFO: Microblog startup [in C:\Users\GIHYEON\anaconda3\envs\GH_project\Grand-Heart-Project\app\__init__.py:48]
2021-07-27 22:13:19,199 INFO: Microblog startup [in C:\Users\GIHYEON\anaconda3\envs\GH_project\Grand-Heart-Project\app\__init__.py:48]
2021-07-27 22:15:19,371 INFO: Microblog startup [in C:\Users\GIHYEON\anaconda3\envs\GH_project\Grand-Heart-Project\app\__init__.py:48]
2021-07-27 22:16:57,926 INFO: Microblog startup [in C:\Users\GIHYEON\anaconda3\envs\GH_project\Grand-Heart-Project\app\__init__.py:48]
2021-07-27 22:21:16,360 INFO: Microblog startup [in C:\Users\GIHYEON\anaconda3\envs\GH_project\Grand-Heart-Project\app\__init__.py:48]
2021-07-27 22:29:44,486 INFO: Microblog startup [in C:\Users\GIHYEON\anaconda3\envs\GH_project\Grand-Heart-Project\app\__init__.py:48]
2021-07-27 22:30:19,077 INFO: Microblog startup [in C:\Users\GIHYEON\anaconda3\envs\GH_project\Grand-Heart-Project\app\__init__.py:48]
2021-07-27 22:31:00,968 INFO: Microblog startup [in C:\Users\GIHYEON\anaconda3\envs\GH_project\Grand-Heart-Project\app\__init__.py:48]
2021-07-27 22:31:41,619 INFO: Microblog startup [in C:\Users\GIHYEON\anaconda3\envs\GH_project\Grand-Heart-Project\app\__init__.py:48]
2021-07-27 22:33:12,284 INFO: Microblog startup [in C:\Users\GIHYEON\anaconda3\envs\GH_project\Grand-Heart-Project\app\__init__.py:48]
2021-07-27 22:34:36,278 INFO: Microblog startup [in C:\Users\GIHYEON\anaconda3\envs\GH_project\Grand-Heart-Project\app\__init__.py:48]
2021-07-27 22:35:28,470 INFO: Microblog startup [in C:\Users\GIHYEON\anaconda3\envs\GH_project\Grand-Heart-Project\app\__init__.py:48]
2021-07-27 22:38:03,265 INFO: Microblog startup [in C:\Users\GIHYEON\anaconda3\envs\GH_project\Grand-Heart-Project\app\__init__.py:48]
2021-07-27 22:40:05,183 INFO: Microblog startup [in C:\Users\GIHYEON\anaconda3\envs\GH_project\Grand-Heart-Project\app\__init__.py:48]
2021-07-27 22:43:29,535 INFO: Microblog startup [in C:\Users\GIHYEON\anaconda3\envs\GH_project\Grand-Heart-Project\app\__init__.py:48]
